[2025-07-03T03:29:57.709+0000] {local_task_job_runner.py:120} INFO - ::group::Pre task execution logs
[2025-07-03T03:29:57.801+0000] {taskinstance.py:2073} INFO - Dependencies all met for dep_context=non-requeueable deps ti=<TaskInstance: sosmed_pipeline.crawl_data scheduled__2025-07-03T02:00:00+00:00 [queued]>
[2025-07-03T03:29:57.819+0000] {taskinstance.py:2073} INFO - Dependencies all met for dep_context=requeueable deps ti=<TaskInstance: sosmed_pipeline.crawl_data scheduled__2025-07-03T02:00:00+00:00 [queued]>
[2025-07-03T03:29:57.820+0000] {taskinstance.py:2303} INFO - Starting attempt 2 of 2
[2025-07-03T03:29:57.850+0000] {taskinstance.py:2327} INFO - Executing <Task(PythonOperator): crawl_data> on 2025-07-03 02:00:00+00:00
[2025-07-03T03:29:57.856+0000] {standard_task_runner.py:63} INFO - Started process 267 to run task
[2025-07-03T03:29:57.865+0000] {standard_task_runner.py:90} INFO - Running: ['***', 'tasks', 'run', 'sosmed_pipeline', 'crawl_data', 'scheduled__2025-07-03T02:00:00+00:00', '--job-id', '5', '--raw', '--subdir', 'DAGS_FOLDER/***_dags.py', '--cfg-path', '/tmp/tmpc_caqwzn']
[2025-07-03T03:29:57.868+0000] {standard_task_runner.py:91} INFO - Job 5: Subtask crawl_data
[2025-07-03T03:29:57.954+0000] {logging_mixin.py:188} WARNING - /home/***/.local/lib/python3.10/site-packages/***/settings.py:195 DeprecationWarning: The sql_alchemy_conn option in [core] has been moved to the sql_alchemy_conn option in [database] - the old setting has been used, but please update your config.
[2025-07-03T03:29:58.199+0000] {task_command.py:426} INFO - Running <TaskInstance: sosmed_pipeline.crawl_data scheduled__2025-07-03T02:00:00+00:00 [running]> on host 56a7b09f6b61
[2025-07-03T03:29:58.506+0000] {taskinstance.py:2644} INFO - Exporting env vars: AIRFLOW_CTX_DAG_OWNER='etl' AIRFLOW_CTX_DAG_ID='sosmed_pipeline' AIRFLOW_CTX_TASK_ID='crawl_data' AIRFLOW_CTX_EXECUTION_DATE='2025-07-03T02:00:00+00:00' AIRFLOW_CTX_TRY_NUMBER='2' AIRFLOW_CTX_DAG_RUN_ID='scheduled__2025-07-03T02:00:00+00:00'
[2025-07-03T03:29:58.507+0000] {taskinstance.py:430} INFO - ::endgroup::
[2025-07-03T03:29:58.527+0000] {airflow_dags.py:19} INFO - [START] Menjalankan script: /app/crawler-service/main.py
[2025-07-03T03:30:01.424+0000] {airflow_dags.py:25} ERROR - [FAILED] Script gagal dijalankan: /app/crawler-service/main.py | Error: Command '['python3', '/app/crawler-service/main.py']' returned non-zero exit status 1.
[2025-07-03T03:30:01.425+0000] {taskinstance.py:441} INFO - ::group::Post task execution logs
[2025-07-03T03:30:01.425+0000] {taskinstance.py:2890} ERROR - Task failed with exception
Traceback (most recent call last):
  File "/opt/airflow/dags/airflow_dags.py", line 22, in run_script
    subprocess.run(['python3',script_path],check=True)
  File "/usr/local/lib/python3.10/subprocess.py", line 526, in run
    raise CalledProcessError(retcode, process.args,
subprocess.CalledProcessError: Command '['python3', '/app/crawler-service/main.py']' returned non-zero exit status 1.

During handling of the above exception, another exception occurred:

Traceback (most recent call last):
  File "/home/airflow/.local/lib/python3.10/site-packages/airflow/models/taskinstance.py", line 465, in _execute_task
    result = _execute_callable(context=context, **execute_callable_kwargs)
  File "/home/airflow/.local/lib/python3.10/site-packages/airflow/models/taskinstance.py", line 432, in _execute_callable
    return execute_callable(context=context, **execute_callable_kwargs)
  File "/home/airflow/.local/lib/python3.10/site-packages/airflow/models/baseoperator.py", line 400, in wrapper
    return func(self, *args, **kwargs)
  File "/home/airflow/.local/lib/python3.10/site-packages/airflow/operators/python.py", line 235, in execute
    return_value = self.execute_callable()
  File "/home/airflow/.local/lib/python3.10/site-packages/airflow/operators/python.py", line 252, in execute_callable
    return self.python_callable(*self.op_args, **self.op_kwargs)
  File "/opt/airflow/dags/airflow_dags.py", line 26, in run_script
    raise RuntimeError(f"Script gagal: {script_path} | {e}")
RuntimeError: Script gagal: /app/crawler-service/main.py | Command '['python3', '/app/crawler-service/main.py']' returned non-zero exit status 1.
[2025-07-03T03:30:01.453+0000] {taskinstance.py:1205} INFO - Marking task as FAILED. dag_id=sosmed_pipeline, task_id=crawl_data, execution_date=20250703T020000, start_date=20250703T032957, end_date=20250703T033001
[2025-07-03T03:30:01.492+0000] {standard_task_runner.py:110} ERROR - Failed to execute job 5 for task crawl_data (Script gagal: /app/crawler-service/main.py | Command '['python3', '/app/crawler-service/main.py']' returned non-zero exit status 1.; 267)
[2025-07-03T03:30:01.506+0000] {local_task_job_runner.py:240} INFO - Task exited with return code 1
[2025-07-03T03:30:01.576+0000] {taskinstance.py:3482} INFO - 0 downstream tasks scheduled from follow-on schedule check
[2025-07-03T03:30:01.589+0000] {local_task_job_runner.py:222} INFO - ::endgroup::
[2025-07-03T03:45:20.261+0000] {local_task_job_runner.py:120} INFO - ::group::Pre task execution logs
[2025-07-03T03:45:20.324+0000] {taskinstance.py:2073} INFO - Dependencies all met for dep_context=non-requeueable deps ti=<TaskInstance: sosmed_pipeline.crawl_data scheduled__2025-07-03T02:00:00+00:00 [queued]>
[2025-07-03T03:45:20.344+0000] {taskinstance.py:2073} INFO - Dependencies all met for dep_context=requeueable deps ti=<TaskInstance: sosmed_pipeline.crawl_data scheduled__2025-07-03T02:00:00+00:00 [queued]>
[2025-07-03T03:45:20.345+0000] {taskinstance.py:2303} INFO - Starting attempt 2 of 2
[2025-07-03T03:45:20.369+0000] {taskinstance.py:2327} INFO - Executing <Task(PythonOperator): crawl_data> on 2025-07-03 02:00:00+00:00
[2025-07-03T03:45:20.374+0000] {standard_task_runner.py:63} INFO - Started process 276 to run task
[2025-07-03T03:45:20.403+0000] {standard_task_runner.py:90} INFO - Running: ['***', 'tasks', 'run', 'sosmed_pipeline', 'crawl_data', 'scheduled__2025-07-03T02:00:00+00:00', '--job-id', '4', '--raw', '--subdir', 'DAGS_FOLDER/***_dags.py', '--cfg-path', '/tmp/tmpjctqmhdn']
[2025-07-03T03:45:20.422+0000] {standard_task_runner.py:91} INFO - Job 4: Subtask crawl_data
[2025-07-03T03:45:20.455+0000] {logging_mixin.py:188} WARNING - /home/***/.local/lib/python3.10/site-packages/***/settings.py:195 DeprecationWarning: The sql_alchemy_conn option in [core] has been moved to the sql_alchemy_conn option in [database] - the old setting has been used, but please update your config.
[2025-07-03T03:45:20.572+0000] {task_command.py:426} INFO - Running <TaskInstance: sosmed_pipeline.crawl_data scheduled__2025-07-03T02:00:00+00:00 [running]> on host f419ff1c1ac4
[2025-07-03T03:45:20.784+0000] {taskinstance.py:2644} INFO - Exporting env vars: AIRFLOW_CTX_DAG_OWNER='etl' AIRFLOW_CTX_DAG_ID='sosmed_pipeline' AIRFLOW_CTX_TASK_ID='crawl_data' AIRFLOW_CTX_EXECUTION_DATE='2025-07-03T02:00:00+00:00' AIRFLOW_CTX_TRY_NUMBER='2' AIRFLOW_CTX_DAG_RUN_ID='scheduled__2025-07-03T02:00:00+00:00'
[2025-07-03T03:45:20.788+0000] {taskinstance.py:430} INFO - ::endgroup::
[2025-07-03T03:45:20.866+0000] {airflow_dags.py:19} INFO - [START] Menjalankan script: /app/crawler-service/main.py
[2025-07-03T03:45:22.786+0000] {airflow_dags.py:25} ERROR - [FAILED] Script gagal dijalankan: /app/crawler-service/main.py | Error: Command '['python3', '/app/crawler-service/main.py']' returned non-zero exit status 1.
[2025-07-03T03:45:22.787+0000] {taskinstance.py:441} INFO - ::group::Post task execution logs
[2025-07-03T03:45:22.788+0000] {taskinstance.py:2890} ERROR - Task failed with exception
Traceback (most recent call last):
  File "/opt/airflow/dags/airflow_dags.py", line 22, in run_script
    subprocess.run(['python3',script_path],check=True)
  File "/usr/local/lib/python3.10/subprocess.py", line 526, in run
    raise CalledProcessError(retcode, process.args,
subprocess.CalledProcessError: Command '['python3', '/app/crawler-service/main.py']' returned non-zero exit status 1.

During handling of the above exception, another exception occurred:

Traceback (most recent call last):
  File "/home/airflow/.local/lib/python3.10/site-packages/airflow/models/taskinstance.py", line 465, in _execute_task
    result = _execute_callable(context=context, **execute_callable_kwargs)
  File "/home/airflow/.local/lib/python3.10/site-packages/airflow/models/taskinstance.py", line 432, in _execute_callable
    return execute_callable(context=context, **execute_callable_kwargs)
  File "/home/airflow/.local/lib/python3.10/site-packages/airflow/models/baseoperator.py", line 400, in wrapper
    return func(self, *args, **kwargs)
  File "/home/airflow/.local/lib/python3.10/site-packages/airflow/operators/python.py", line 235, in execute
    return_value = self.execute_callable()
  File "/home/airflow/.local/lib/python3.10/site-packages/airflow/operators/python.py", line 252, in execute_callable
    return self.python_callable(*self.op_args, **self.op_kwargs)
  File "/opt/airflow/dags/airflow_dags.py", line 26, in run_script
    raise RuntimeError(f"Script gagal: {script_path} | {e}")
RuntimeError: Script gagal: /app/crawler-service/main.py | Command '['python3', '/app/crawler-service/main.py']' returned non-zero exit status 1.
[2025-07-03T03:45:22.815+0000] {taskinstance.py:1205} INFO - Marking task as FAILED. dag_id=sosmed_pipeline, task_id=crawl_data, execution_date=20250703T020000, start_date=20250703T034520, end_date=20250703T034522
[2025-07-03T03:45:22.832+0000] {standard_task_runner.py:110} ERROR - Failed to execute job 4 for task crawl_data (Script gagal: /app/crawler-service/main.py | Command '['python3', '/app/crawler-service/main.py']' returned non-zero exit status 1.; 276)
[2025-07-03T03:45:22.859+0000] {local_task_job_runner.py:240} INFO - Task exited with return code 1
[2025-07-03T03:45:22.901+0000] {taskinstance.py:3482} INFO - 0 downstream tasks scheduled from follow-on schedule check
[2025-07-03T03:45:22.906+0000] {local_task_job_runner.py:222} INFO - ::endgroup::
