[2025-07-02T02:00:01.427+0000] {taskinstance.py:1956} INFO - Dependencies all met for dep_context=non-requeueable deps ti=<TaskInstance: sosmed_pipeline.crawl_data scheduled__2025-07-02T01:00:00+00:00 [queued]>
[2025-07-02T02:00:01.440+0000] {taskinstance.py:1956} INFO - Dependencies all met for dep_context=requeueable deps ti=<TaskInstance: sosmed_pipeline.crawl_data scheduled__2025-07-02T01:00:00+00:00 [queued]>
[2025-07-02T02:00:01.441+0000] {taskinstance.py:2170} INFO - Starting attempt 1 of 2
[2025-07-02T02:00:01.460+0000] {taskinstance.py:2191} INFO - Executing <Task(PythonOperator): crawl_data> on 2025-07-02 01:00:00+00:00
[2025-07-02T02:00:01.466+0000] {standard_task_runner.py:60} INFO - Started process 797 to run task
[2025-07-02T02:00:01.471+0000] {standard_task_runner.py:87} INFO - Running: ['***', 'tasks', 'run', 'sosmed_pipeline', 'crawl_data', 'scheduled__2025-07-02T01:00:00+00:00', '--job-id', '24', '--raw', '--subdir', 'DAGS_FOLDER/***_dags.py', '--cfg-path', '/tmp/tmp3ga_fxgg']
[2025-07-02T02:00:01.474+0000] {standard_task_runner.py:88} INFO - Job 24: Subtask crawl_data
[2025-07-02T02:00:01.500+0000] {logging_mixin.py:188} WARNING - /home/***/.local/lib/python3.8/site-packages/***/settings.py:194 DeprecationWarning: The sql_alchemy_conn option in [core] has been moved to the sql_alchemy_conn option in [database] - the old setting has been used, but please update your config.
[2025-07-02T02:00:01.559+0000] {task_command.py:423} INFO - Running <TaskInstance: sosmed_pipeline.crawl_data scheduled__2025-07-02T01:00:00+00:00 [running]> on host 0bb9681e74da
[2025-07-02T02:00:01.716+0000] {taskinstance.py:2480} INFO - Exporting env vars: AIRFLOW_CTX_DAG_OWNER='etl' AIRFLOW_CTX_DAG_ID='sosmed_pipeline' AIRFLOW_CTX_TASK_ID='crawl_data' AIRFLOW_CTX_EXECUTION_DATE='2025-07-02T01:00:00+00:00' AIRFLOW_CTX_TRY_NUMBER='1' AIRFLOW_CTX_DAG_RUN_ID='scheduled__2025-07-02T01:00:00+00:00'
[2025-07-02T02:00:01.717+0000] {airflow_dags.py:19} INFO - [START] Menjalankan script: /app/crawler-service/main.py
[2025-07-02T02:00:01.854+0000] {airflow_dags.py:25} ERROR - [FAILED] Script gagal dijalankan: /app/crawler-service/main.py | Error: Command '['python3', '/app/crawler-service/main.py']' returned non-zero exit status 1.
[2025-07-02T02:00:01.855+0000] {taskinstance.py:2698} ERROR - Task failed with exception
Traceback (most recent call last):
  File "/opt/airflow/dags/airflow_dags.py", line 22, in run_script
    subprocess.run(['python3',script_path],check=True)
  File "/usr/local/lib/python3.8/subprocess.py", line 516, in run
    raise CalledProcessError(retcode, process.args,
subprocess.CalledProcessError: Command '['python3', '/app/crawler-service/main.py']' returned non-zero exit status 1.

During handling of the above exception, another exception occurred:

Traceback (most recent call last):
  File "/home/airflow/.local/lib/python3.8/site-packages/airflow/models/taskinstance.py", line 433, in _execute_task
    result = execute_callable(context=context, **execute_callable_kwargs)
  File "/home/airflow/.local/lib/python3.8/site-packages/airflow/operators/python.py", line 199, in execute
    return_value = self.execute_callable()
  File "/home/airflow/.local/lib/python3.8/site-packages/airflow/operators/python.py", line 216, in execute_callable
    return self.python_callable(*self.op_args, **self.op_kwargs)
  File "/opt/airflow/dags/airflow_dags.py", line 26, in run_script
    raise RuntimeError(f"Script gagal: {script_path} | {e}")
RuntimeError: Script gagal: /app/crawler-service/main.py | Command '['python3', '/app/crawler-service/main.py']' returned non-zero exit status 1.
[2025-07-02T02:00:01.875+0000] {taskinstance.py:1138} INFO - Marking task as UP_FOR_RETRY. dag_id=sosmed_pipeline, task_id=crawl_data, execution_date=20250702T010000, start_date=20250702T020001, end_date=20250702T020001
[2025-07-02T02:00:01.895+0000] {standard_task_runner.py:107} ERROR - Failed to execute job 24 for task crawl_data (Script gagal: /app/crawler-service/main.py | Command '['python3', '/app/crawler-service/main.py']' returned non-zero exit status 1.; 797)
[2025-07-02T02:00:01.904+0000] {local_task_job_runner.py:234} INFO - Task exited with return code 1
[2025-07-02T02:00:01.945+0000] {taskinstance.py:3280} INFO - 0 downstream tasks scheduled from follow-on schedule check
