[2025-07-02T11:45:57.236+0000] {local_task_job_runner.py:120} INFO - ::group::Pre task execution logs
[2025-07-02T11:45:57.318+0000] {taskinstance.py:2073} INFO - Dependencies all met for dep_context=non-requeueable deps ti=<TaskInstance: sosmed_pipeline.crawl_data manual__2025-07-02T11:40:54.383691+00:00 [queued]>
[2025-07-02T11:45:57.331+0000] {taskinstance.py:2073} INFO - Dependencies all met for dep_context=requeueable deps ti=<TaskInstance: sosmed_pipeline.crawl_data manual__2025-07-02T11:40:54.383691+00:00 [queued]>
[2025-07-02T11:45:57.332+0000] {taskinstance.py:2303} INFO - Starting attempt 2 of 2
[2025-07-02T11:45:57.353+0000] {taskinstance.py:2327} INFO - Executing <Task(PythonOperator): crawl_data> on 2025-07-02 11:40:54.383691+00:00
[2025-07-02T11:45:57.359+0000] {standard_task_runner.py:63} INFO - Started process 233 to run task
[2025-07-02T11:45:57.371+0000] {standard_task_runner.py:90} INFO - Running: ['***', 'tasks', 'run', 'sosmed_pipeline', 'crawl_data', 'manual__2025-07-02T11:40:54.383691+00:00', '--job-id', '41', '--raw', '--subdir', 'DAGS_FOLDER/***_dags.py', '--cfg-path', '/tmp/tmprm368a1_']
[2025-07-02T11:45:57.378+0000] {standard_task_runner.py:91} INFO - Job 41: Subtask crawl_data
[2025-07-02T11:45:57.422+0000] {logging_mixin.py:188} WARNING - /home/***/.local/lib/python3.10/site-packages/***/settings.py:195 DeprecationWarning: The sql_alchemy_conn option in [core] has been moved to the sql_alchemy_conn option in [database] - the old setting has been used, but please update your config.
[2025-07-02T11:45:57.493+0000] {task_command.py:426} INFO - Running <TaskInstance: sosmed_pipeline.crawl_data manual__2025-07-02T11:40:54.383691+00:00 [running]> on host b5ed631ecaa2
[2025-07-02T11:45:57.736+0000] {taskinstance.py:2644} INFO - Exporting env vars: AIRFLOW_CTX_DAG_OWNER='etl' AIRFLOW_CTX_DAG_ID='sosmed_pipeline' AIRFLOW_CTX_TASK_ID='crawl_data' AIRFLOW_CTX_EXECUTION_DATE='2025-07-02T11:40:54.383691+00:00' AIRFLOW_CTX_TRY_NUMBER='2' AIRFLOW_CTX_DAG_RUN_ID='manual__2025-07-02T11:40:54.383691+00:00'
[2025-07-02T11:45:57.738+0000] {taskinstance.py:430} INFO - ::endgroup::
[2025-07-02T11:45:57.761+0000] {airflow_dags.py:19} INFO - [START] Menjalankan script: /app/crawler-service/main.py
[2025-07-02T11:45:58.378+0000] {airflow_dags.py:25} ERROR - [FAILED] Script gagal dijalankan: /app/crawler-service/main.py | Error: Command '['python3', '/app/crawler-service/main.py']' returned non-zero exit status 1.
[2025-07-02T11:45:58.379+0000] {taskinstance.py:441} INFO - ::group::Post task execution logs
[2025-07-02T11:45:58.380+0000] {taskinstance.py:2890} ERROR - Task failed with exception
Traceback (most recent call last):
  File "/opt/airflow/dags/airflow_dags.py", line 22, in run_script
    subprocess.run(['python3',script_path],check=True)
  File "/usr/local/lib/python3.10/subprocess.py", line 526, in run
    raise CalledProcessError(retcode, process.args,
subprocess.CalledProcessError: Command '['python3', '/app/crawler-service/main.py']' returned non-zero exit status 1.

During handling of the above exception, another exception occurred:

Traceback (most recent call last):
  File "/home/airflow/.local/lib/python3.10/site-packages/airflow/models/taskinstance.py", line 465, in _execute_task
    result = _execute_callable(context=context, **execute_callable_kwargs)
  File "/home/airflow/.local/lib/python3.10/site-packages/airflow/models/taskinstance.py", line 432, in _execute_callable
    return execute_callable(context=context, **execute_callable_kwargs)
  File "/home/airflow/.local/lib/python3.10/site-packages/airflow/models/baseoperator.py", line 400, in wrapper
    return func(self, *args, **kwargs)
  File "/home/airflow/.local/lib/python3.10/site-packages/airflow/operators/python.py", line 235, in execute
    return_value = self.execute_callable()
  File "/home/airflow/.local/lib/python3.10/site-packages/airflow/operators/python.py", line 252, in execute_callable
    return self.python_callable(*self.op_args, **self.op_kwargs)
  File "/opt/airflow/dags/airflow_dags.py", line 26, in run_script
    raise RuntimeError(f"Script gagal: {script_path} | {e}")
RuntimeError: Script gagal: /app/crawler-service/main.py | Command '['python3', '/app/crawler-service/main.py']' returned non-zero exit status 1.
[2025-07-02T11:45:58.397+0000] {taskinstance.py:1205} INFO - Marking task as FAILED. dag_id=sosmed_pipeline, task_id=crawl_data, execution_date=20250702T114054, start_date=20250702T114557, end_date=20250702T114558
[2025-07-02T11:45:58.415+0000] {standard_task_runner.py:110} ERROR - Failed to execute job 41 for task crawl_data (Script gagal: /app/crawler-service/main.py | Command '['python3', '/app/crawler-service/main.py']' returned non-zero exit status 1.; 233)
[2025-07-02T11:45:58.454+0000] {local_task_job_runner.py:240} INFO - Task exited with return code 1
[2025-07-02T11:45:58.493+0000] {taskinstance.py:3482} INFO - 0 downstream tasks scheduled from follow-on schedule check
[2025-07-02T11:45:58.500+0000] {local_task_job_runner.py:222} INFO - ::endgroup::
