[2025-07-01T16:20:50.495+0000] {taskinstance.py:1956} INFO - Dependencies all met for dep_context=non-requeueable deps ti=<TaskInstance: sosmed_pipeline.crawl_data manual__2025-07-01T16:19:39.656340+00:00 [queued]>
[2025-07-01T16:20:50.510+0000] {taskinstance.py:1956} INFO - Dependencies all met for dep_context=requeueable deps ti=<TaskInstance: sosmed_pipeline.crawl_data manual__2025-07-01T16:19:39.656340+00:00 [queued]>
[2025-07-01T16:20:50.512+0000] {taskinstance.py:2170} INFO - Starting attempt 1 of 2
[2025-07-01T16:20:50.538+0000] {taskinstance.py:2191} INFO - Executing <Task(PythonOperator): crawl_data> on 2025-07-01 16:19:39.656340+00:00
[2025-07-01T16:20:50.544+0000] {standard_task_runner.py:60} INFO - Started process 285 to run task
[2025-07-01T16:20:50.550+0000] {standard_task_runner.py:87} INFO - Running: ['***', 'tasks', 'run', 'sosmed_pipeline', 'crawl_data', 'manual__2025-07-01T16:19:39.656340+00:00', '--job-id', '5', '--raw', '--subdir', 'DAGS_FOLDER/***_dags.py', '--cfg-path', '/tmp/tmpneq375ly']
[2025-07-01T16:20:50.569+0000] {standard_task_runner.py:88} INFO - Job 5: Subtask crawl_data
[2025-07-01T16:20:50.592+0000] {logging_mixin.py:188} WARNING - /home/***/.local/lib/python3.8/site-packages/***/settings.py:194 DeprecationWarning: The sql_alchemy_conn option in [core] has been moved to the sql_alchemy_conn option in [database] - the old setting has been used, but please update your config.
[2025-07-01T16:20:50.654+0000] {task_command.py:423} INFO - Running <TaskInstance: sosmed_pipeline.crawl_data manual__2025-07-01T16:19:39.656340+00:00 [running]> on host 0bb9681e74da
[2025-07-01T16:20:50.795+0000] {taskinstance.py:2480} INFO - Exporting env vars: AIRFLOW_CTX_DAG_OWNER='etl' AIRFLOW_CTX_DAG_ID='sosmed_pipeline' AIRFLOW_CTX_TASK_ID='crawl_data' AIRFLOW_CTX_EXECUTION_DATE='2025-07-01T16:19:39.656340+00:00' AIRFLOW_CTX_TRY_NUMBER='1' AIRFLOW_CTX_DAG_RUN_ID='manual__2025-07-01T16:19:39.656340+00:00'
[2025-07-01T16:20:50.797+0000] {taskinstance.py:2698} ERROR - Task failed with exception
Traceback (most recent call last):
  File "/home/airflow/.local/lib/python3.8/site-packages/airflow/models/taskinstance.py", line 433, in _execute_task
    result = execute_callable(context=context, **execute_callable_kwargs)
  File "/home/airflow/.local/lib/python3.8/site-packages/airflow/operators/python.py", line 199, in execute
    return_value = self.execute_callable()
  File "/home/airflow/.local/lib/python3.8/site-packages/airflow/operators/python.py", line 216, in execute_callable
    return self.python_callable(*self.op_args, **self.op_kwargs)
  File "/opt/airflow/dags/airflow_dags.py", line 16, in run_script
    base_dir = os.gatenv('BASE_DIR','/app')
AttributeError: module 'os' has no attribute 'gatenv'
[2025-07-01T16:20:50.813+0000] {taskinstance.py:1138} INFO - Marking task as UP_FOR_RETRY. dag_id=sosmed_pipeline, task_id=crawl_data, execution_date=20250701T161939, start_date=20250701T162050, end_date=20250701T162050
[2025-07-01T16:20:50.832+0000] {standard_task_runner.py:107} ERROR - Failed to execute job 5 for task crawl_data (module 'os' has no attribute 'gatenv'; 285)
[2025-07-01T16:20:50.856+0000] {local_task_job_runner.py:234} INFO - Task exited with return code 1
[2025-07-01T16:20:50.893+0000] {taskinstance.py:3280} INFO - 0 downstream tasks scheduled from follow-on schedule check
