[2025-07-03T03:24:52.337+0000] {local_task_job_runner.py:120} INFO - ::group::Pre task execution logs
[2025-07-03T03:24:52.399+0000] {taskinstance.py:2073} INFO - Dependencies all met for dep_context=non-requeueable deps ti=<TaskInstance: sosmed_pipeline.crawl_data manual__2025-07-03T03:24:50.388791+00:00 [queued]>
[2025-07-03T03:24:52.413+0000] {taskinstance.py:2073} INFO - Dependencies all met for dep_context=requeueable deps ti=<TaskInstance: sosmed_pipeline.crawl_data manual__2025-07-03T03:24:50.388791+00:00 [queued]>
[2025-07-03T03:24:52.414+0000] {taskinstance.py:2303} INFO - Starting attempt 1 of 2
[2025-07-03T03:24:52.434+0000] {taskinstance.py:2327} INFO - Executing <Task(PythonOperator): crawl_data> on 2025-07-03 03:24:50.388791+00:00
[2025-07-03T03:24:52.446+0000] {standard_task_runner.py:63} INFO - Started process 212 to run task
[2025-07-03T03:24:52.450+0000] {standard_task_runner.py:90} INFO - Running: ['***', 'tasks', 'run', 'sosmed_pipeline', 'crawl_data', 'manual__2025-07-03T03:24:50.388791+00:00', '--job-id', '3', '--raw', '--subdir', 'DAGS_FOLDER/***_dags.py', '--cfg-path', '/tmp/tmpuebludd3']
[2025-07-03T03:24:52.462+0000] {standard_task_runner.py:91} INFO - Job 3: Subtask crawl_data
[2025-07-03T03:24:52.523+0000] {logging_mixin.py:188} WARNING - /home/***/.local/lib/python3.10/site-packages/***/settings.py:195 DeprecationWarning: The sql_alchemy_conn option in [core] has been moved to the sql_alchemy_conn option in [database] - the old setting has been used, but please update your config.
[2025-07-03T03:24:52.636+0000] {task_command.py:426} INFO - Running <TaskInstance: sosmed_pipeline.crawl_data manual__2025-07-03T03:24:50.388791+00:00 [running]> on host 56a7b09f6b61
[2025-07-03T03:24:52.977+0000] {taskinstance.py:2644} INFO - Exporting env vars: AIRFLOW_CTX_DAG_OWNER='etl' AIRFLOW_CTX_DAG_ID='sosmed_pipeline' AIRFLOW_CTX_TASK_ID='crawl_data' AIRFLOW_CTX_EXECUTION_DATE='2025-07-03T03:24:50.388791+00:00' AIRFLOW_CTX_TRY_NUMBER='1' AIRFLOW_CTX_DAG_RUN_ID='manual__2025-07-03T03:24:50.388791+00:00'
[2025-07-03T03:24:52.981+0000] {taskinstance.py:430} INFO - ::endgroup::
[2025-07-03T03:24:53.031+0000] {airflow_dags.py:19} INFO - [START] Menjalankan script: /app/crawler-service/main.py
[2025-07-03T03:24:56.074+0000] {airflow_dags.py:25} ERROR - [FAILED] Script gagal dijalankan: /app/crawler-service/main.py | Error: Command '['python3', '/app/crawler-service/main.py']' returned non-zero exit status 1.
[2025-07-03T03:24:56.075+0000] {taskinstance.py:441} INFO - ::group::Post task execution logs
[2025-07-03T03:24:56.076+0000] {taskinstance.py:2890} ERROR - Task failed with exception
Traceback (most recent call last):
  File "/opt/airflow/dags/airflow_dags.py", line 22, in run_script
    subprocess.run(['python3',script_path],check=True)
  File "/usr/local/lib/python3.10/subprocess.py", line 526, in run
    raise CalledProcessError(retcode, process.args,
subprocess.CalledProcessError: Command '['python3', '/app/crawler-service/main.py']' returned non-zero exit status 1.

During handling of the above exception, another exception occurred:

Traceback (most recent call last):
  File "/home/airflow/.local/lib/python3.10/site-packages/airflow/models/taskinstance.py", line 465, in _execute_task
    result = _execute_callable(context=context, **execute_callable_kwargs)
  File "/home/airflow/.local/lib/python3.10/site-packages/airflow/models/taskinstance.py", line 432, in _execute_callable
    return execute_callable(context=context, **execute_callable_kwargs)
  File "/home/airflow/.local/lib/python3.10/site-packages/airflow/models/baseoperator.py", line 400, in wrapper
    return func(self, *args, **kwargs)
  File "/home/airflow/.local/lib/python3.10/site-packages/airflow/operators/python.py", line 235, in execute
    return_value = self.execute_callable()
  File "/home/airflow/.local/lib/python3.10/site-packages/airflow/operators/python.py", line 252, in execute_callable
    return self.python_callable(*self.op_args, **self.op_kwargs)
  File "/opt/airflow/dags/airflow_dags.py", line 26, in run_script
    raise RuntimeError(f"Script gagal: {script_path} | {e}")
RuntimeError: Script gagal: /app/crawler-service/main.py | Command '['python3', '/app/crawler-service/main.py']' returned non-zero exit status 1.
[2025-07-03T03:24:56.102+0000] {taskinstance.py:1205} INFO - Marking task as UP_FOR_RETRY. dag_id=sosmed_pipeline, task_id=crawl_data, execution_date=20250703T032450, start_date=20250703T032452, end_date=20250703T032456
[2025-07-03T03:24:56.123+0000] {standard_task_runner.py:110} ERROR - Failed to execute job 3 for task crawl_data (Script gagal: /app/crawler-service/main.py | Command '['python3', '/app/crawler-service/main.py']' returned non-zero exit status 1.; 212)
[2025-07-03T03:24:56.134+0000] {local_task_job_runner.py:240} INFO - Task exited with return code 1
[2025-07-03T03:24:56.169+0000] {taskinstance.py:3482} INFO - 0 downstream tasks scheduled from follow-on schedule check
[2025-07-03T03:24:56.173+0000] {local_task_job_runner.py:222} INFO - ::endgroup::
