[2025-07-01T16:25:51.686+0000] {taskinstance.py:1956} INFO - Dependencies all met for dep_context=non-requeueable deps ti=<TaskInstance: sosmed_pipeline.crawl_data manual__2025-07-01T16:19:17.489394+00:00 [queued]>
[2025-07-01T16:25:51.699+0000] {taskinstance.py:1956} INFO - Dependencies all met for dep_context=requeueable deps ti=<TaskInstance: sosmed_pipeline.crawl_data manual__2025-07-01T16:19:17.489394+00:00 [queued]>
[2025-07-01T16:25:51.700+0000] {taskinstance.py:2170} INFO - Starting attempt 2 of 2
[2025-07-01T16:25:51.750+0000] {taskinstance.py:2191} INFO - Executing <Task(PythonOperator): crawl_data> on 2025-07-01 16:19:17.489394+00:00
[2025-07-01T16:25:51.766+0000] {standard_task_runner.py:60} INFO - Started process 205 to run task
[2025-07-01T16:25:51.773+0000] {standard_task_runner.py:87} INFO - Running: ['***', 'tasks', 'run', 'sosmed_pipeline', 'crawl_data', 'manual__2025-07-01T16:19:17.489394+00:00', '--job-id', '8', '--raw', '--subdir', 'DAGS_FOLDER/***_dags.py', '--cfg-path', '/tmp/tmp2czb2gtm']
[2025-07-01T16:25:51.779+0000] {standard_task_runner.py:88} INFO - Job 8: Subtask crawl_data
[2025-07-01T16:25:51.832+0000] {logging_mixin.py:188} WARNING - /home/***/.local/lib/python3.8/site-packages/***/settings.py:194 DeprecationWarning: The sql_alchemy_conn option in [core] has been moved to the sql_alchemy_conn option in [database] - the old setting has been used, but please update your config.
[2025-07-01T16:25:51.902+0000] {task_command.py:423} INFO - Running <TaskInstance: sosmed_pipeline.crawl_data manual__2025-07-01T16:19:17.489394+00:00 [running]> on host 0bb9681e74da
[2025-07-01T16:25:52.035+0000] {taskinstance.py:2480} INFO - Exporting env vars: AIRFLOW_CTX_DAG_OWNER='etl' AIRFLOW_CTX_DAG_ID='sosmed_pipeline' AIRFLOW_CTX_TASK_ID='crawl_data' AIRFLOW_CTX_EXECUTION_DATE='2025-07-01T16:19:17.489394+00:00' AIRFLOW_CTX_TRY_NUMBER='2' AIRFLOW_CTX_DAG_RUN_ID='manual__2025-07-01T16:19:17.489394+00:00'
[2025-07-01T16:25:52.038+0000] {taskinstance.py:2698} ERROR - Task failed with exception
Traceback (most recent call last):
  File "/home/airflow/.local/lib/python3.8/site-packages/airflow/models/taskinstance.py", line 433, in _execute_task
    result = execute_callable(context=context, **execute_callable_kwargs)
  File "/home/airflow/.local/lib/python3.8/site-packages/airflow/operators/python.py", line 199, in execute
    return_value = self.execute_callable()
  File "/home/airflow/.local/lib/python3.8/site-packages/airflow/operators/python.py", line 216, in execute_callable
    return self.python_callable(*self.op_args, **self.op_kwargs)
  File "/opt/airflow/dags/airflow_dags.py", line 16, in run_script
    base_dir = os.gatenv('BASE_DIR','/app')
AttributeError: module 'os' has no attribute 'gatenv'
[2025-07-01T16:25:52.053+0000] {taskinstance.py:1138} INFO - Marking task as FAILED. dag_id=sosmed_pipeline, task_id=crawl_data, execution_date=20250701T161917, start_date=20250701T162551, end_date=20250701T162552
[2025-07-01T16:25:52.073+0000] {standard_task_runner.py:107} ERROR - Failed to execute job 8 for task crawl_data (module 'os' has no attribute 'gatenv'; 205)
[2025-07-01T16:25:52.089+0000] {local_task_job_runner.py:234} INFO - Task exited with return code 1
[2025-07-01T16:25:52.143+0000] {taskinstance.py:3280} INFO - 0 downstream tasks scheduled from follow-on schedule check
