[2025-07-02T12:05:02.050+0000] {local_task_job_runner.py:120} INFO - ::group::Pre task execution logs
[2025-07-02T12:05:02.096+0000] {taskinstance.py:2073} INFO - Dependencies all met for dep_context=non-requeueable deps ti=<TaskInstance: sosmed_pipeline.crawl_data scheduled__2025-07-02T11:00:00+00:00 [queued]>
[2025-07-02T12:05:02.152+0000] {taskinstance.py:2073} INFO - Dependencies all met for dep_context=requeueable deps ti=<TaskInstance: sosmed_pipeline.crawl_data scheduled__2025-07-02T11:00:00+00:00 [queued]>
[2025-07-02T12:05:02.153+0000] {taskinstance.py:2303} INFO - Starting attempt 2 of 2
[2025-07-02T12:05:02.183+0000] {taskinstance.py:2327} INFO - Executing <Task(PythonOperator): crawl_data> on 2025-07-02 11:00:00+00:00
[2025-07-02T12:05:02.187+0000] {standard_task_runner.py:63} INFO - Started process 424 to run task
[2025-07-02T12:05:02.192+0000] {standard_task_runner.py:90} INFO - Running: ['***', 'tasks', 'run', 'sosmed_pipeline', 'crawl_data', 'scheduled__2025-07-02T11:00:00+00:00', '--job-id', '43', '--raw', '--subdir', 'DAGS_FOLDER/***_dags.py', '--cfg-path', '/tmp/tmppgxgvgab']
[2025-07-02T12:05:02.195+0000] {standard_task_runner.py:91} INFO - Job 43: Subtask crawl_data
[2025-07-02T12:05:02.216+0000] {logging_mixin.py:188} WARNING - /home/***/.local/lib/python3.10/site-packages/***/settings.py:195 DeprecationWarning: The sql_alchemy_conn option in [core] has been moved to the sql_alchemy_conn option in [database] - the old setting has been used, but please update your config.
[2025-07-02T12:05:02.266+0000] {task_command.py:426} INFO - Running <TaskInstance: sosmed_pipeline.crawl_data scheduled__2025-07-02T11:00:00+00:00 [running]> on host b5ed631ecaa2
[2025-07-02T12:05:02.401+0000] {taskinstance.py:2644} INFO - Exporting env vars: AIRFLOW_CTX_DAG_OWNER='etl' AIRFLOW_CTX_DAG_ID='sosmed_pipeline' AIRFLOW_CTX_TASK_ID='crawl_data' AIRFLOW_CTX_EXECUTION_DATE='2025-07-02T11:00:00+00:00' AIRFLOW_CTX_TRY_NUMBER='2' AIRFLOW_CTX_DAG_RUN_ID='scheduled__2025-07-02T11:00:00+00:00'
[2025-07-02T12:05:02.402+0000] {taskinstance.py:430} INFO - ::endgroup::
[2025-07-02T12:05:02.415+0000] {airflow_dags.py:19} INFO - [START] Menjalankan script: /app/crawler-service/main.py
[2025-07-02T12:05:02.767+0000] {airflow_dags.py:25} ERROR - [FAILED] Script gagal dijalankan: /app/crawler-service/main.py | Error: Command '['python3', '/app/crawler-service/main.py']' returned non-zero exit status 1.
[2025-07-02T12:05:02.768+0000] {taskinstance.py:441} INFO - ::group::Post task execution logs
[2025-07-02T12:05:02.769+0000] {taskinstance.py:2890} ERROR - Task failed with exception
Traceback (most recent call last):
  File "/opt/airflow/dags/airflow_dags.py", line 22, in run_script
    subprocess.run(['python3',script_path],check=True)
  File "/usr/local/lib/python3.10/subprocess.py", line 526, in run
    raise CalledProcessError(retcode, process.args,
subprocess.CalledProcessError: Command '['python3', '/app/crawler-service/main.py']' returned non-zero exit status 1.

During handling of the above exception, another exception occurred:

Traceback (most recent call last):
  File "/home/airflow/.local/lib/python3.10/site-packages/airflow/models/taskinstance.py", line 465, in _execute_task
    result = _execute_callable(context=context, **execute_callable_kwargs)
  File "/home/airflow/.local/lib/python3.10/site-packages/airflow/models/taskinstance.py", line 432, in _execute_callable
    return execute_callable(context=context, **execute_callable_kwargs)
  File "/home/airflow/.local/lib/python3.10/site-packages/airflow/models/baseoperator.py", line 400, in wrapper
    return func(self, *args, **kwargs)
  File "/home/airflow/.local/lib/python3.10/site-packages/airflow/operators/python.py", line 235, in execute
    return_value = self.execute_callable()
  File "/home/airflow/.local/lib/python3.10/site-packages/airflow/operators/python.py", line 252, in execute_callable
    return self.python_callable(*self.op_args, **self.op_kwargs)
  File "/opt/airflow/dags/airflow_dags.py", line 26, in run_script
    raise RuntimeError(f"Script gagal: {script_path} | {e}")
RuntimeError: Script gagal: /app/crawler-service/main.py | Command '['python3', '/app/crawler-service/main.py']' returned non-zero exit status 1.
[2025-07-02T12:05:02.784+0000] {taskinstance.py:1205} INFO - Marking task as FAILED. dag_id=sosmed_pipeline, task_id=crawl_data, execution_date=20250702T110000, start_date=20250702T120502, end_date=20250702T120502
[2025-07-02T12:05:02.802+0000] {standard_task_runner.py:110} ERROR - Failed to execute job 43 for task crawl_data (Script gagal: /app/crawler-service/main.py | Command '['python3', '/app/crawler-service/main.py']' returned non-zero exit status 1.; 424)
[2025-07-02T12:05:02.824+0000] {local_task_job_runner.py:240} INFO - Task exited with return code 1
[2025-07-02T12:05:02.853+0000] {taskinstance.py:3482} INFO - 0 downstream tasks scheduled from follow-on schedule check
[2025-07-02T12:05:02.860+0000] {local_task_job_runner.py:222} INFO - ::endgroup::
